Workbook

Sheet DASHBOARD
B1: AEROSOL PLANT · INSTALLATION DASHBOARD
B2: Last Updated | C2: =TODAY() -> 46163
B4: Total Tasks | C4: Completed | D4: In Progress | E4: Not Started | F4: Blocked
B5: =COUNTA(TRACKER!$A$3:$A$131) -> 129 | C5: =COUNTIF(TRACKER!$G$3:$G$131,"Completed") -> 44 | D5: =COUNTIF(TRACKER!$G$3:$G$131,"In Progress") -> 37 | E5: =COUNTIF(TRACKER!$G$3:$G$131,"Not Started") -> 40 | F5: =COUNTIF(TRACKER!$G$3:$G$131,"Blocked") -> 4
B8: MACHINE SECTIONS
B9: Machine (tap to view tasks) | C9: ⚡ Elec. Pending | D9: ⚙ Mech. Pending | E9: Total Pending | F9: ✓ Done
B10: Press | C10: =COUNTIFS(TRACKER!$B$3:$B$131,"Press",TRACKER!$C$3:$C$131,"Electrical",TRACKER!$G$3:$G$131,"<>Completed") -> 1 | D10: =COUNTIFS(TRACKER!$B$3:$B$131,"Press",TRACKER!$C$3:$C$131,"Mechanical",TRACKER!$G$3:$G$131,"<>Completed") -> 14 | E10: =C10+D10 -> 15 | F10: =COUNTIFS(TRACKER!$B$3:$B$131,"Press",TRACKER!$G$3:$G$131,"Completed") -> 14
B11: Trimming | C11: =COUNTIFS(TRACKER!$B$3:$B$131,"Trimming",TRACKER!$C$3:$C$131,"Electrical",TRACKER!$G$3:$G$131,"<>Completed") -> 1 | D11: =COUNTIFS(TRACKER!$B$3:$B$131,"Trimming",TRACKER!$C$3:$C$131,"Mechanical",TRACKER!$G$3:$G$131,"<>Completed") -> 2 | E11: =C11+D11 -> 3 | F11: =COUNTIFS(TRACKER!$B$3:$B$131,"Trimming",TRACKER!$G$3:$G$131,"Completed") -> 6
B12: Washing | C12: =COUNTIFS(TRACKER!$B$3:$B$131,"Washing",TRACKER!$C$3:$C$131,"Electrical",TRACKER!$G$3:$G$131,"<>Completed") -> 3 | D12: =COUNTIFS(TRACKER!$B$3:$B$131,"Washing",TRACKER!$C$3:$C$131,"Mechanical",TRACKER!$G$3:$G$131,"<>Completed") -> 13 | E12: =C12+D12 -> 16 | F12: =COUNTIFS(TRACKER!$B$3:$B$131,"Washing",TRACKER!$G$3:$G$131,"Completed") -> 2
B13: Lacquer | C13: =COUNTIFS(TRACKER!$B$3:$B$131,"Lacquer",TRACKER!$C$3:$C$131,"Electrical",TRACKER!$G$3:$G$131,"<>Completed") -> 2 | D13: =COUNTIFS(TRACKER!$B$3:$B$131,"Lacquer",TRACKER!$C$3:$C$131,"Mechanical",TRACKER!$G$3:$G$131,"<>Completed") -> 2 | E13: =C13+D13 -> 4 | F13: =COUNTIFS(TRACKER!$B$3:$B$131,"Lacquer",TRACKER!$G$3:$G$131,"Completed") -> 7
B14: Base Coat | C14: =COUNTIFS(TRACKER!$B$3:$B$131,"Base Coat",TRACKER!$C$3:$C$131,"Electrical",TRACKER!$G$3:$G$131,"<>Completed") -> 0 | D14: =COUNTIFS(TRACKER!$B$3:$B$131,"Base Coat",TRACKER!$C$3:$C$131,"Mechanical",TRACKER!$G$3:$G$131,"<>Completed") -> 1 | E14: =C14+D14 -> 1 | F14: =COUNTIFS(TRACKER!$B$3:$B$131,"Base Coat",TRACKER!$G$3:$G$131,"Completed") -> 3
B15: Printing | C15: =COUNTIFS(TRACKER!$B$3:$B$131,"Printing",TRACKER!$C$3:$C$131,"Electrical",TRACKER!$G$3:$G$131,"<>Completed") -> 3 | D15: =COUNTIFS(TRACKER!$B$3:$B$131,"Printing",TRACKER!$C$3:$C$131,"Mechanical",TRACKER!$G$3:$G$131,"<>Completed") -> 7 | E15: =C15+D15 -> 10 | F15: =COUNTIFS(TRACKER!$B$3:$B$131,"Printing",TRACKER!$G$3:$G$131,"Completed") -> 2
B16: Over Varnish | C16: =COUNTIFS(TRACKER!$B$3:$B$131,"Over Varnish",TRACKER!$C$3:$C$131,"Electrical",TRACKER!$G$3:$G$131,"<>Completed") -> 0 | D16: =COUNTIFS(TRACKER!$B$3:$B$131,"Over Varnish",TRACKER!$C$3:$C$131,"Mechanical",TRACKER!$G$3:$G$131,"<>Completed") -> 1 | E16: =C16+D16 -> 1 | F16: =COUNTIFS(TRACKER!$B$3:$B$131,"Over Varnish",TRACKER!$G$3:$G$131,"Completed") -> 4
B17: Main Oven | C17: =COUNTIFS(TRACKER!$B$3:$B$131,"Main Oven",TRACKER!$C$3:$C$131,"Electrical",TRACKER!$G$3:$G$131,"<>Completed") -> 0 | D17: =COUNTIFS(TRACKER!$B$3:$B$131,"Main Oven",TRACKER!$C$3:$C$131,"Mechanical",TRACKER!$G$3:$G$131,"<>Completed") -> 0 | E17: =C17+D17 -> 0 | F17: =COUNTIFS(TRACKER!$B$3:$B$131,"Main Oven",TRACKER!$G$3:$G$131,"Completed") -> 3
B18: Necking | C18: =COUNTIFS(TRACKER!$B$3:$B$131,"Necking",TRACKER!$C$3:$C$131,"Electrical",TRACKER!$G$3:$G$131,"<>Completed") -> 1 | D18: =COUNTIFS(TRACKER!$B$3:$B$131,"Necking",TRACKER!$C$3:$C$131,"Mechanical",TRACKER!$G$3:$G$131,"<>Completed") -> 4 | E18: =C18+D18 -> 5 | F18: =COUNTIFS(TRACKER!$B$3:$B$131,"Necking",TRACKER!$G$3:$G$131,"Completed") -> 1
B19: Mixer | C19: =COUNTIFS(TRACKER!$B$3:$B$131,"Mixer",TRACKER!$C$3:$C$131,"Electrical",TRACKER!$G$3:$G$131,"<>Completed") -> 1 | D19: =COUNTIFS(TRACKER!$B$3:$B$131,"Mixer",TRACKER!$C$3:$C$131,"Mechanical",TRACKER!$G$3:$G$131,"<>Completed") -> 0 | E19: =C19+D19 -> 1 | F19: =COUNTIFS(TRACKER!$B$3:$B$131,"Mixer",TRACKER!$G$3:$G$131,"Completed") -> 1
B20: General | C20: =COUNTIFS(TRACKER!$B$3:$B$131,"General",TRACKER!$C$3:$C$131,"Electrical",TRACKER!$G$3:$G$131,"<>Completed") -> 10 | D20: =COUNTIFS(TRACKER!$B$3:$B$131,"General",TRACKER!$C$3:$C$131,"Mechanical",TRACKER!$G$3:$G$131,"<>Completed") -> 19 | E20: =C20+D20 -> 29 | F20: =COUNTIFS(TRACKER!$B$3:$B$131,"General",TRACKER!$G$3:$G$131,"Completed") -> 1
B23: PENDING BY PRIORITY
B24: High Priority | E24: =COUNTIFS(TRACKER!$E$3:$E$131,"High",TRACKER!$G$3:$G$131,"<>Completed") -> 49
B25: Medium Priority | E25: =COUNTIFS(TRACKER!$E$3:$E$131,"Medium",TRACKER!$G$3:$G$131,"<>Completed") -> 26
B26: Low Priority | E26: =COUNTIFS(TRACKER!$E$3:$E$131,"Low",TRACKER!$G$3:$G$131,"<>Completed") -> 10
B29: STATUS REFERENCE
B30: In Progress | C30: Not Started | D30: Blocked | E30: Completed | F30: Pending Procurement

Sheet TRACKER
A1: AEROSOL PLANT · INSTALLATION TRACKER | I1: ← Dashboard
A2: # | B2: Machine | C2: Category | D2: Task Description | E2: Priority | F2: Progress | G2: Status | H2: Remarks | I2: Updated
A3: 1 | B3: Press | C3: Electrical | D3: Close all electrical panels and cable trays | E3: High | F3: 0.1 | G3: In Progress
A4: 2 | B4: Press | C4: Electrical | D4: SOV pneumatic press clutch service | E4: – | F4: 1 | G4: Completed
A5: 3 | B5: Press | C5: Electrical | D5: Hopper motor installation and testing (Dry Run) | E5: – | F5: 1 | G5: Completed
A6: 4 | B6: Press | C6: Electrical | D6: Hopper Motor installation | E6: – | F6: 1 | G6: Completed
A7: 5 | B7: Press | C7: Electrical | D7: Cable trays installation | E7: – | F7: 1 | G7: Completed
A8: 6 | B8: Press | C8: Mechanical | D8: Slug Feeding Hopper with switch — complete unit | E8: High | F8: 0.5 | G8: In Progress
A9: 7 | B9: Press | C9: Mechanical | D9: Gear Oil Lubrication pumping system setup | E9: High | F9: 0.4 | G9: In Progress | H9: Pump sent for repairing
A10: 8 | B10: Press | C10: Mechanical | D10: Welding & fixing gear oil tank brackets and sheet | E10: Medium | F10: 0.4 | G10: In Progress
A11: 9 | B11: Press | C11: Mechanical | D11: Press machine auto lubrication — pending tasks | E11: High | F11: 0.3 | G11: In Progress | H11: Procurement in process
A12: 10 | B12: Press | C12: Mechanical | D12: Tools for press machine — urgent procurement | E12: High | F12: 0.2 | G12: In Progress | H12: In progress
A13: 11 | B13: Press | C13: Mechanical | D13: 02 Dust collection pipes to be installed | E13: Medium | F13: 0 | G13: Not Started
A14: 12 | B14: Press | C14: Mechanical | D14: Dust Collection blower — connection with piping | E14: Medium | F14: 0 | G14: Not Started | H14: Blower to be procured
A15: 13 | B15: Press | C15: Mechanical | D15: Fix lubrication tray with slope for drainage | E15: Medium | F15: 0 | G15: Not Started
A16: 14 | B16: Press | C16: Mechanical | D16: Oil collection tank — place directly under tray | E16: Medium | F16: 0 | G16: Not Started
A17: 15 | B17: Press | C17: Mechanical | D17: Operator Platform (incomplete stand) to be made | E17: Low | F17: 0 | G17: Not Started
A18: 16 | B18: Press | C18: Mechanical | D18: Damping rubber pads over slug feeding tray | E18: Low | F18: 0 | G18: Not Started
A19: 17 | B19: Press | C19: Mechanical | D19: Scoop (chamach) required for slug handling | E19: Low | F19: 0 | G19: Not Started | H19: Khalid sb
A20: 18 | B20: Press | C20: Mechanical | D20: Baling machine check from local vendor | E20: Low | F20: 0 | G20: Not Started | H20: Khalid sb
A21: 19 | B21: Press | C21: Mechanical | D21: Press machine auto running on slug | E21: High | F21: 0 | G21: Not Started | H21: Awaiting pending task completion
A22: 20 | B22: Press | C22: Mechanical | D22: Auto gripper fitting / checking | E22: – | F22: 1 | G22: Completed
A23: 21 | B23: Press | C23: Mechanical | D23: Slug Holder channel | E23: – | F23: 1 | G23: Completed
A24: 22 | B24: Press | C24: Mechanical | D24: Press main slide installation | E24: – | F24: 1 | G24: Completed
A25: 23 | B25: Press | C25: Mechanical | D25: Press conveyor fixation | E25: – | F25: 1 | G25: Completed
A26: 24 | B26: Press | C26: Mechanical | D26: Oil pump motor repairing | E26: – | F26: 1 | G26: Completed
A27: 25 | B27: Press | C27: Mechanical | D27: Press & Trimming compressor line fixed | E27: – | F27: 1 | G27: Completed
A28: 26 | B28: Press | C28: Mechanical | D28: Press Clutch NRV repaired | E28: – | F28: 1 | G28: Completed
A29: 27 | B29: Press | C29: Mechanical | D29: Oil pump replacing and troubleshooting | E29: – | F29: 1 | G29: Completed
A30: 28 | B30: Press | C30: Mechanical | D30: Press timing and alignment with testing | E30: – | F30: 1 | G30: Completed
A31: 29 | B31: Press | C31: Mechanical | D31: Die & punch stroke setting | E31: – | F31: 1 | G31: Completed
A32: 30 | B32: Trimming | C32: Electrical | D32: Scrap collector wiring and troubleshooting | E32: High | F32: 0.9 | G32: In Progress | H32: Magnetic switch faulty — to be changed
A33: 31 | B33: Trimming | C33: Electrical | D33: Electrical Panel checked / Tested | E33: – | F33: 1 | G33: Completed
A34: 32 | B34: Trimming | C34: Electrical | D34: Startup main motor | E34: – | F34: 1 | G34: Completed
A35: 33 | B35: Trimming | C35: Electrical | D35: Pneumatic and Electrical operation check | E35: – | F35: 1 | G35: Completed
A36: 34 | B36: Trimming | C36: Mechanical | D36: Oiling / greasing / parts replacement / testing | E36: High | F36: 0.8 | G36: In Progress | H36: Oil pump maintenance pending
A37: 35 | B37: Trimming | C37: Mechanical | D37: Trimming machine dry run | E37: High | F37: 0 | G37: Blocked | H37: Dry run awaiting — cutter blade sent for sharpening
A38: 36 | B38: Trimming | C38: Mechanical | D38: Trimming startup | E38: – | F38: 1 | G38: Completed
A39: 37 | B39: Trimming | C39: Mechanical | D39: Conveyor alignment — Trimming to Washing | E39: – | F39: 1 | G39: Completed
A40: 38 | B40: Trimming | C40: Mechanical | D40: Conveyor — Press to Trimming input | E40: – | F40: 1 | G40: Completed
...

Sheet HOW TO UPDATE
B1: HOW TO UPDATE — QUICK GUIDE
B2: COLUMN / STEP | C2: INSTRUCTION
B3: COLUMN | C3: WHAT TO DO
B4: Machine | C4: Click the cell — a dropdown appears. Pick the machine name.
B5: Category | C5: Pick Electrical or Mechanical from the dropdown.
B6: Task Description | C6: Type the task clearly and briefly.
B7: Priority | C7: High = urgent / blocking. Medium = important. Low = when possible.
B8: Progress | C8: Type a number: 0 = not started, 50 = halfway done, 100 = complete.
B9: Status | C9: Pick from dropdown: Not Started / In Progress / Completed / Blocked / Pending Procurement.
B10: Remarks | C10: Short notes — vendor, reason for delay, Khalid sb instruction, etc.
B11: Updated | C11: Type today's date when you update any row.
B12: Add a new task | C12: Scroll to the bottom. Type in the next empty row. All dropdowns work there too.
B13: Filter by machine | C13: Click the filter arrow (▼) on the Machine column. Tick only the machine you want.
... B16: Back to Dashboard | C16: In the Tracker, click '← Dashboard' in the top-right corner of the sheet.
