Workbook

Sheet DASHBOARD
B1: AEROSOL PLANT · Installation & Commissioning Tracker
B2: Last Updated | C2: =TODAY()
B4: Overall % | C4: Total Tasks | D4: Completed | E4: In Progress | F4: Not Started | G4: Hold | H4: Pending Procurement
B5: =IF(COUNTA(TRACKER!$B$4:$B$1002)=0, 0, AVERAGEIF(TRACKER!$B$4:$B$1002,"<>", TRACKER!$F$4:$F$1002)) | C5: =COUNTA(TRACKER!$B$4:$B$1002) | D5: =COUNTIF(TRACKER!$G$4:$G$1002,"Completed") | E5: =COUNTIF(TRACKER!$G$4:$G$1002,"In Progress") | F5: =COUNTIF(TRACKER!$G$4:$G$1002,"Not Started") | G5: =COUNTIF(TRACKER!$G$4:$G$1002,"Blocked") | H5: =COUNTIF(TRACKER!$G$4:$G$1002,"Pending Procurement")
B7: MACHINE SECTIONS
B8: Machine | C8: Elec. Pending | D8: Mech. Pending | E8: Other Pending | F8: Total Pending | G8: Completed | H8: Overall %
B9: =HYPERLINK("#TRACKER!B" & (MATCH("Tumbler", TRACKER!$B$4:$B$1002, 0) + 2), "⚙️ Tumbler") | C9: =COUNTIFS(TRACKER!$B$4:$B$1002,"tumbler",TRACKER!$C$4:$C$1002,"Electrical",TRACKER!$G$4:$G$1002,"<>Completed") | D9: =COUNTIFS(TRACKER!$B$4:$B$1002,"tumbler",TRACKER!$C$4:$C$1002,"Mechanical",TRACKER!$G$4:$G$1002,"<>Completed") | E9: =COUNTIFS(TRACKER!$B$4:$B$1002,"tumbler",TRACKER!$G$4:$G$1002,"<>Completed")-COUNTIFS(TRACKER!$B$4:$B$1002,"tumbler",TRACKER!$C$4:$C$1002,"Electrical",TRACKER!$G$4:$G$1002,"<>Completed")-COUNTIFS(TRACKER!$B$4:$B$1002,"tumbler",TRACKER!$C$4:$C$1002,"Mechanical",TRACKER!$G$4:$G$1002,"<>Completed") | F9: =COUNTIFS(TRACKER!$B$4:$B$1002,"tumbler",TRACKER!$G$4:$G$1002,"<>Completed") | G9: =COUNTIFS(TRACKER!$B$4:$B$1002,"tumbler",TRACKER!$G$4:$G$1002,"Completed") | H9: =IFERROR(AVERAGEIF(TRACKER!$B$4:$B$1002,"tumbler",TRACKER!$F$4:$F$1002),0)
B10: =HYPERLINK("#TRACKER!B" & (MATCH("Press", TRACKER!$B$4:$B$1002, 0) + 2), "⚙️ Press") | C10: =COUNTIFS(TRACKER!$B$4:$B$1002,"Press",TRACKER!$C$4:$C$1002,"Electrical",TRACKER!$G$4:$G$1002,"<>Completed") | D10: =COUNTIFS(TRACKER!$B$4:$B$1002,"Press",TRACKER!$C$4:$C$1002,"Mechanical",TRACKER!$G$4:$G$1002,"<>Completed") | E10: =COUNTIFS(TRACKER!$B$4:$B$1002,"Press",TRACKER!$G$4:$G$1002,"<>Completed")-COUNTIFS(TRACKER!$B$4:$B$1002,"Press",TRACKER!$C$4:$C$1002,"Electrical",TRACKER!$G$4:$G$1002,"<>Completed")-COUNTIFS(TRACKER!$B$4:$B$1002,"Press",TRACKER!$C$4:$C$1002,"Mechanical",TRACKER!$G$4:$G$1002,"<>Completed") | F10: =COUNTIFS(TRACKER!$B$4:$B$1002,"Press",TRACKER!$G$4:$G$1002,"<>Completed") | G10: =COUNTIFS(TRACKER!$B$4:$B$1002,"Press",TRACKER!$G$4:$G$1002,"Completed") | H10: =IFERROR(AVERAGEIF(TRACKER!$B$4:$B$1002,"Press",TRACKER!$F$4:$F$1002),0)
B11: =HYPERLINK("#TRACKER!B" & (MATCH("Trimming", TRACKER!$B$4:$B$1002, 0) + 2), "✂️ Trimming") | C11: =COUNTIFS(TRACKER!$B$4:$B$1002,"Trimming",TRACKER!$C$4:$C$1002,"Electrical",TRACKER!$G$4:$G$1002,"<>Completed") | D11: =COUNTIFS(TRACKER!$B$4:$B$1002,"Trimming",TRACKER!$C$4:$C$1002,"Mechanical",TRACKER!$G$4:$G$1002,"<>Completed") | E11: =COUNTIFS(TRACKER!$B$4:$B$1002,"Trimming",TRACKER!$G$4:$G$1002,"<>Completed")-COUNTIFS(TRACKER!$B$4:$B$1002,"Trimming",TRACKER!$C$4:$C$1002,"Electrical",TRACKER!$G$4:$G$1002,"<>Completed")-COUNTIFS(TRACKER!$B$4:$B$1002,"Trimming",TRACKER!$C$4:$C$1002,"Mechanical",TRACKER!$G$4:$G$1002,"<>Completed") | F11: =COUNTIFS(TRACKER!$B$4:$B$1002,"Trimming",TRACKER!$G$4:$G$1002,"<>Completed") | G11: =COUNTIFS(TRACKER!$B$4:$B$1002,"Trimming",TRACKER!$G$4:$G$1002,"Completed") | H11: =IFERROR(AVERAGEIF(TRACKER!$B$4:$B$1002,"Trimming",TRACKER!$F$4:$F$1002),0)
B12: =HYPERLINK("#TRACKER!B" & (MATCH("Washing", TRACKER!$B$4:$B$1002, 0) + 2), "💧 Washing") | C12: =COUNTIFS(TRACKER!$B$4:$B$1002,"Washing",TRACKER!$C$4:$C$1002,"Electrical",TRACKER!$G$4:$G$1002,"<>Completed") | D12: =COUNTIFS(TRACKER!$B$4:$B$1002,"Washing",TRACKER!$C$4:$C$1002,"Mechanical",TRACKER!$G$4:$G$1002,"<>Completed") | E12: =COUNTIFS(TRACKER!$B$4:$B$1002,"Washing",TRACKER!$G$4:$G$1002,"<>Completed")-COUNTIFS(TRACKER!$B$4:$B$1002,"Washing",TRACKER!$C$4:$C$1002,"Electrical",TRACKER!$G$4:$G$1002,"<>Completed")-COUNTIFS(TRACKER!$B$4:$B$1002,"Washing",TRACKER!$C$4:$C$1002,"Mechanical",TRACKER!$G$4:$G$1002,"<>Completed") | F12: =COUNTIFS(TRACKER!$B$4:$B$1002,"Washing",TRACKER!$G$4:$G$1002,"<>Completed") | G12: =COUNTIFS(TRACKER!$B$4:$B$1002,"Washing",TRACKER!$G$4:$G$1002,"Completed") | H12: =IFERROR(AVERAGEIF(TRACKER!$B$4:$B$1002,"Washing",TRACKER!$F$4:$F$1002),0)
B13: =HYPERLINK("#TRACKER!B" & (MATCH("Lacquer", TRACKER!$B$4:$B$1002, 0) + 2), "🎨 Lacquer") | C13: =COUNTIFS(TRACKER!$B$4:$B$1002,"Lacquer",TRACKER!$C$4:$C$1002,"Electrical",TRACKER!$G$4:$G$1002,"<>Completed") | D13: =COUNTIFS(TRACKER!$B$4:$B$1002,"Lacquer",TRACKER!$C$4:$C$1002,"Mechanical",TRACKER!$G$4:$G$1002,"<>Completed") | E13: =COUNTIFS(TRACKER!$B$4:$B$1002,"Lacquer",TRACKER!$G$4:$G$1002,"<>Completed")-COUNTIFS(TRACKER!$B$4:$B$1002,"Lacquer",TRACKER!$C$4:$C$1002,"Electrical",TRACKER!$G$4:$G$1002,"<>Completed")-COUNTIFS(TRACKER!$B$4:$B$1002,"Lacquer",TRACKER!$C$4:$C$1002,"Mechanical",TRACKER!$G$4:$G$1002,"<>Completed") | F13: =COUNTIFS(TRACKER!$B$4:$B$1002,"Lacquer",TRACKER!$G$4:$G$1002,"<>Completed") | G13: =COUNTIFS(TRACKER!$B$4:$B$1002,"Lacquer",TRACKER!$G$4:$G$1002,"Completed") | H13: =IFERROR(AVERAGEIF(TRACKER!$B$4:$B$1002,"Lacquer",TRACKER!$F$4:$F$1002),0)
B14: =HYPERLINK("#TRACKER!B" & (MATCH("Accumulator", TRACKER!$B$4:$B$1002, 0) + 2), "🔄 Accumulator") | C14: =COUNTIFS(TRACKER!$B$4:$B$1002,"Accumulator",TRACKER!$C$4:$C$1002,"Electrical",TRACKER!$G$4:$G$1002,"<>Completed") | D14: =COUNTIFS(TRACKER!$B$4:$B$1002,"Accumulator",TRACKER!$C$4:$C$1002,"Mechanical",TRACKER!$G$4:$G$1002,"<>Completed") | E14: =COUNTIFS(TRACKER!$B$4:$B$1002,"Accumulator",TRACKER!$G$4:$G$1002,"<>Completed")-COUNTIFS(TRACKER!$B$4:$B$1002,"Accumulator",TRACKER!$C$4:$C$1002,"Electrical",TRACKER!$G$4:$G$1002,"<>Completed")-COUNTIFS(TRACKER!$B$4:$B$1002,"Accumulator",TRACKER!$C$4:$C$1002,"Mechanical",TRACKER!$G$4:$G$1002,"<>Completed") | F14: =COUNTIFS(TRACKER!$B$4:$B$1002,"Accumulator",TRACKER!$G$4:$G$1002,"<>Completed") | G14: =COUNTIFS(TRACKER!$B$4:$B$1002,"Accumulator",TRACKER!$G$4:$G$1002,"Completed") | H14: =IFERROR(AVERAGEIF(TRACKER!$B$4:$B$1002,"Accumulator",TRACKER!$F$4:$F$1002),0)
B15: =HYPERLINK("#TRACKER!B" & (MATCH("Base Coat", TRACKER!$B$4:$B$1002, 0) + 2), "🖌️ Base Coat") | C15: =COUNTIFS(TRACKER!$B$4:$B$1002,"Base Coat",TRACKER!$C$4:$C$1002,"Electrical",TRACKER!$G$4:$G$1002,"<>Completed") | D15: =COUNTIFS(TRACKER!$B$4:$B$1002,"Base Coat",TRACKER!$C$4:$C$1002,"Mechanical",TRACKER!$G$4:$G$1002,"<>Completed") | E15: =COUNTIFS(TRACKER!$B$4:$B$1002,"Base Coat",TRACKER!$G$4:$G$1002,"<>Completed")-COUNTIFS(TRACKER!$B$4:$B$1002,"Base Coat",TRACKER!$C$4:$C$1002,"Electrical",TRACKER!$G$4:$G$1002,"<>Completed")-COUNTIFS(TRACKER!$B$4:$B$1002,"Base Coat",TRACKER!$C$4:$C$1002,"Mechanical",TRACKER!$G$4:$G$1002,"<>Completed") | F15: =COUNTIFS(TRACKER!$B$4:$B$1002,"Base Coat",TRACKER!$G$4:$G$1002,"<>Completed") | G15: =COUNTIFS(TRACKER!$B$4:$B$1002,"Base Coat",TRACKER!$G$4:$G$1002,"Completed") | H15: =IFERROR(AVERAGEIF(TRACKER!$B$4:$B$1002,"Base Coat",TRACKER!$F$4:$F$1002),0)
B16: =HYPERLINK("#TRACKER!B" & (MATCH("Printing", TRACKER!$B$4:$B$1002, 0) + 2), "🖨️ Printing") | C16: =COUNTIFS(TRACKER!$B$4:$B$1002,"Printing",TRACKER!$C$4:$C$1002,"Electrical",TRACKER!$G$4:$G$1002,"<>Completed") | D16: =COUNTIFS(TRACKER!$B$4:$B$1002,"Printing",TRACKER!$C$4:$C$1002,"Mechanical",TRACKER!$G$4:$G$1002,"<>Completed") | E16: =COUNTIFS(TRACKER!$B$4:$B$1002,"Printing",TRACKER!$G$4:$G$1002,"<>Completed")-COUNTIFS(TRACKER!$B$4:$B$1002,"Printing",TRACKER!$C$4:$C$1002,"Electrical",TRACKER!$G$4:$G$1002,"<>Completed")-COUNTIFS(TRACKER!$B$4:$B$1002,"Printing",TRACKER!$C$4:$C$1002,"Mechanical",TRACKER!$G$4:$G$1002,"<>Completed") | F16: =COUNTIFS(TRACKER!$B$4:$B$1002,"Printing",TRACKER!$G$4:$G$1002,"<>Completed") | G16: =COUNTIFS(TRACKER!$B$4:$B$1002,"Printing",TRACKER!$G$4:$G$1002,"Completed") | H16: =IFERROR(AVERAGEIF(TRACKER!$B$4:$B$1002,"Printing",TRACKER!$F$4:$F$1002),0)
B17: =HYPERLINK("#TRACKER!B" & (MATCH("Over Varnish", TRACKER!$B$4:$B$1002, 0) + 2), "✨ Over Varnish") | C17: =COUNTIFS(TRACKER!$B$4:$B$1002,"Over Varnish",TRACKER!$C$4:$C$1002,"Electrical",TRACKER!$G$4:$G$1002,"<>Completed") | D17: =COUNTIFS(TRACKER!$B$4:$B$1002,"Over Varnish",TRACKER!$C$4:$C$1002,"Mechanical",TRACKER!$G$4:$G$1002,"<>Completed") | E17: =COUNTIFS(TRACKER!$B$4:$B$1002,"Over Varnish",TRACKER!$G$4:$G$1002,"<>Completed")-COUNTIFS(TRACKER!$B$4:$B$1002,"Over Varnish",TRACKER!$C$4:$C$1002,"Electrical",TRACKER!$G$4:$G$1002,"<>Completed")-COUNTIFS(TRACKER!$B$4:$B$1002,"Over Varnish",TRACKER!$C$4:$C$1002,"Mechanical",TRACKER!$G$4:$G$1002,"<>Completed") | F17: =COUNTIFS(TRACKER!$B$4:$B$1002,"Over Varnish",TRACKER!$G$4:$G$1002,"<>Completed") | G17: =COUNTIFS(TRACKER!$B$4:$B$1002,"Over Varnish",TRACKER!$G$4:$G$1002,"Completed") | H17: =IFERROR(AVERAGEIF(TRACKER!$B$4:$B$1002,"Over Varnish",TRACKER!$F$4:$F$1002),0)
B18: =HYPERLINK("#TRACKER!B" & (MATCH("decoration Oven", TRACKER!$B$4:$B$1002, 0) + 2), "🔥 decoration Oven") | C18: =COUNTIFS(TRACKER!$B$4:$B$1002,"decoration Oven",TRACKER!$C$4:$C$1002,"Electrical",TRACKER!$G$4:$G$1002,"<>Completed") | D18: =COUNTIFS(TRACKER!$B$4:$B$1002,"decoration Oven",TRACKER!$C$4:$C$1002,"Mechanical",TRACKER!$G$4:$G$1002,"<>Completed") | E18: =COUNTIFS(TRACKER!$B$4:$B$1002,"decoration Oven",TRACKER!$G$4:$G$1002,"<>Completed")-COUNTIFS(TRACKER!$B$4:$B$1002,"decoration Oven",TRACKER!$C$4:$C$1002,"Electrical",TRACKER!$G$4:$G$1002,"<>Completed")-COUNTIFS(TRACKER!$B$4:$B$1002,"decoration Oven",TRACKER!$C$4:$C$1002,"Mechanical",TRACKER!$G$4:$G$1002,"<>Completed") | F18: =COUNTIFS(TRACKER!$B$4:$B$1002,"decoration Oven",TRACKER!$G$4:$G$1002,"<>Completed") | G18: =COUNTIFS(TRACKER!$B$4:$B$1002,"decoration Oven",TRACKER!$G$4:$G$1002,"Completed") | H18: =IFERROR(AVERAGEIF(TRACKER!$B$4:$B$1002,"decoration Oven",TRACKER!$F$4:$F$1002),0)
B19: =HYPERLINK("#TRACKER!B" & (MATCH("Necking", TRACKER!$B$4:$B$1002, 0) + 2), "🔩 Necking") | C19: =COUNTIFS(TRACKER!$B$4:$B$1002,"Necking",TRACKER!$C$4:$C$1002,"Electrical",TRACKER!$G$4:$G$1002,"<>Completed") | D19: =COUNTIFS(TRACKER!$B$4:$B$1002,"Necking",TRACKER!$C$4:$C$1002,"Mechanical",TRACKER!$G$4:$G$1002,"<>Completed") | E19: =COUNTIFS(TRACKER!$B$4:$B$1002,"Necking",TRACKER!$G$4:$G$1002,"<>Completed")-COUNTIFS(TRACKER!$B$4:$B$1002,"Necking",TRACKER!$C$4:$C$1002,"Electrical",TRACKER!$G$4:$G$1002,"<>Completed")-COUNTIFS(TRACKER!$B$4:$B$1002,"Necking",TRACKER!$C$4:$C$1002,"Mechanical",TRACKER!$G$4:$G$1002,"<>Completed") | F19: =COUNTIFS(TRACKER!$B$4:$B$1002,"Necking",TRACKER!$G$4:$G$1002,"<>Completed") | G19: =COUNTIFS(TRACKER!$B$4:$B$1002,"Necking",TRACKER!$G$4:$G$1002,"Completed") | H19: =IFERROR(AVERAGEIF(TRACKER!$B$4:$B$1002,"Necking",TRACKER!$F$4:$F$1002),0)
B20: =HYPERLINK("#TRACKER!B" & (MATCH("Auto strapping machine", TRACKER!$B$4:$B$1002, 0) + 2), "📦 Auto strapping machine") | C20: =COUNTIFS(TRACKER!$B$4:$B$1002,"Auto strapping machine",TRACKER!$C$4:$C$1002,"Electrical",TRACKER!$G$4:$G$1002,"<>Completed") | D20: =COUNTIFS(TRACKER!$B$4:$B$1002,"Auto strapping machine",TRACKER!$C$4:$C$1002,"Mechanical",TRACKER!$G$4:$G$1002,"<>Completed") | E20: =COUNTIFS(TRACKER!$B$4:$B$1002,"Auto strapping machine",TRACKER!$G$4:$G$1002,"<>Completed")-COUNTIFS(TRACKER!$B$4:$B$1002,"Auto strapping machine",TRACKER!$C$4:$C$1002,"Electrical",TRACKER!$G$4:$G$1002,"<>Completed")-COUNTIFS(TRACKER!$B$4:$B$1002,"Auto strapping machine",TRACKER!$C$4:$C$1002,"Mechanical",TRACKER!$G$4:$G$1002,"<>Completed") | F20: =COUNTIFS(TRACKER!$B$4:$B$1002,"Auto strapping machine",TRACKER!$G$4:$G$1002,"<>Completed") | G20: =COUNTIFS(TRACKER!$B$4:$B$1002,"Auto strapping machine",TRACKER!$G$4:$G$1002,"Completed") | H20: =IFERROR(AVERAGEIF(TRACKER!$B$4:$B$1002,"Auto strapping machine",TRACKER!$F$4:$F$1002),0)
B21: =HYPERLINK("#TRACKER!B" & (MATCH("Manual Strapping Machine", TRACKER!$B$4:$B$1002, 0) + 2), "📦 Manual strapping machine") | C21: =COUNTIFS(TRACKER!$B$4:$B$1002,"Manual Strapping Machine",TRACKER!$C$4:$C$1002,"Electrical",TRACKER!$G$4:$G$1002,"<>Completed") | D21: =COUNTIFS(TRACKER!$B$4:$B$1002,"Manual Strapping Machine",TRACKER!$C$4:$C$1002,"Mechanical",TRACKER!$G$4:$G$1002,"<>Completed") | E21: =COUNTIFS(TRACKER!$B$4:$B$1002,"Manual Strapping Machine",TRACKER!$G$4:$G$1002,"<>Completed")-COUNTIFS(TRACKER!$B$4:$B$1002,"Manual Strapping Machine",TRACKER!$C$4:$C$1002,"Electrical",TRACKER!$G$4:$G$1002,"<>Completed")-COUNTIFS(TRACKER!$B$4:$B$1002,"Manual Strapping Machine",TRACKER!$C$4:$C$1002,"Mechanical",TRACKER!$G$4:$G$1002,"<>Completed") | F21: =COUNTIFS(TRACKER!$B$4:$B$1002,"Manual Strapping Machine",TRACKER!$G$4:$G$1002,"<>Completed") | G21: =COUNTIFS(TRACKER!$B$4:$B$1002,"Manual Strapping Machine",TRACKER!$G$4:$G$1002,"Completed") | H21: =IFERROR(AVERAGEIF(TRACKER!$B$4:$B$1002,"Manual Strapping Machine",TRACKER!$F$4:$F$1002),0)
B22: =HYPERLINK("#TRACKER!B" & (MATCH("Compressor", TRACKER!$B$4:$B$1002, 0) + 2), "💨 Compressor") | C22: =COUNTIFS(TRACKER!$B$4:$B$1002,"Compressor",TRACKER!$C$4:$C$1002,"Electrical",TRACKER!$G$4:$G$1002,"<>Completed") | D22: =COUNTIFS(TRACKER!$B$4:$B$1002,"Compressor",TRACKER!$C$4:$C$1002,"Mechanical",TRACKER!$G$4:$G$1002,"<>Completed") | E22: =COUNTIFS(TRACKER!$B$4:$B$1002,"Compressor",TRACKER!$G$4:$G$1002,"<>Completed")-COUNTIFS(TRACKER!$B$4:$B$1002,"Compressor",TRACKER!$C$4:$C$1002,"Electrical",TRACKER!$G$4:$G$1002,"<>Completed")-COUNTIFS(TRACKER!$B$4:$B$1002,"Compressor",TRACKER!$C$4:$C$1002,"Mechanical",TRACKER!$G$4:$G$1002,"<>Completed") | F22: =COUNTIFS(TRACKER!$B$4:$B$1002,"Compressor",TRACKER!$G$4:$G$1002,"<>Completed") | G22: =COUNTIFS(TRACKER!$B$4:$B$1002,"Compressor",TRACKER!$G$4:$G$1002,"Completed") | H22: =IFERROR(AVERAGEIF(TRACKER!$B$4:$B$1002,"Compressor",TRACKER!$F$4:$F$1002),0)
B23: =HYPERLINK("#TRACKER!B" & (MATCH("Main Power Distribution", TRACKER!$B$4:$B$1002, 0) + 2), "⚡ Main Power Distribution") | C23: =COUNTIFS(TRACKER!$B$4:$B$1002,"Main Power Distribution",TRACKER!$C$4:$C$1002,"Electrical",TRACKER!$G$4:$G$1002,"<>Completed") | D23: =COUNTIFS(TRACKER!$B$4:$B$1002,"Main Power Distribution",TRACKER!$C$4:$C$1002,"Mechanical",TRACKER!$G$4:$G$1002,"<>Completed") | E23: =COUNTIFS(TRACKER!$B$4:$B$1002,"Main Power Distribution",TRACKER!$G$4:$G$1002,"<>Completed")-COUNTIFS(TRACKER!$B$4:$B$1002,"Main Power Distribution",TRACKER!$C$4:$C$1002,"Electrical",TRACKER!$G$4:$G$1002,"<>Completed")-COUNTIFS(TRACKER!$B$4:$B$1002,"Main Power Distribution",TRACKER!$C$4:$C$1002,"Mechanical",TRACKER!$G$4:$G$1002,"<>Completed") | F23: =COUNTIFS(TRACKER!$B$4:$B$1002,"Main Power Distribution",TRACKER!$G$4:$G$1002,"<>Completed") | G23: =COUNTIFS(TRACKER!$B$4:$B$1002,"Main Power Distribution",TRACKER!$G$4:$G$1002,"Completed") | H23: =IFERROR(AVERAGEIF(TRACKER!$B$4:$B$1002,"Main Power Distribution",TRACKER!$F$4:$F$1002),0)
B24: =HYPERLINK("#TRACKER!B" & (MATCH("General", TRACKER!$B$4:$B$1002, 0) + 2), "📋 General") | C24: =COUNTIFS(TRACKER!$B$4:$B$1002,"General",TRACKER!$C$4:$C$1002,"Electrical",TRACKER!$G$4:$G$1002,"<>Completed") | D24: =COUNTIFS(TRACKER!$B$4:$B$1002,"General",TRACKER!$C$4:$C$1002,"Mechanical",TRACKER!$G$4:$G$1002,"<>Completed") | E24: =COUNTIFS(TRACKER!$B$4:$B$1002,"General",TRACKER!$G$4:$G$1002,"<>Completed")-COUNTIFS(TRACKER!$B$4:$B$1002,"General",TRACKER!$C$4:$C$1002,"Electrical",TRACKER!$G$4:$G$1002,"<>Completed")-COUNTIFS(TRACKER!$B$4:$B$1002,"General",TRACKER!$C$4:$C$1002,"Mechanical",TRACKER!$G$4:$G$1002,"<>Completed") | F24: =COUNTIFS(TRACKER!$B$4:$B$1002,"General",TRACKER!$G$4:$G$1002,"<>Completed") | G24: =COUNTIFS(TRACKER!$B$4:$B$1002,"General",TRACKER!$G$4:$G$1002,"Completed") | H24: =IFERROR(AVERAGEIF(TRACKER!$B$4:$B$1002,"General",TRACKER!$F$4:$F$1002),0)
B26: PENDING BY PRIORITY
B27: High Priority | F27: =COUNTIFS(TRACKER!$E$4:$E$1002,"High",TRACKER!$G$4:$G$1002,"<>Completed")
B28: Medium Priority | F28: =COUNTIFS(TRACKER!$E$4:$E$1002,"Medium",TRACKER!$G$4:$G$1002,"<>Completed")
B29: Low Priority | F29: =COUNTIFS(TRACKER!$E$4:$E$1002,"Low",TRACKER!$G$4:$G$1002,"<>Completed")
B31: STATUS REFERENCE
B32: In Progress | C32: Not Started | D32: Blocked | E32: Completed | F32: Pending Procurement

Sheet TRACKER
A1: AEROSOL PLANT · INSTALLATION TRACKER | J1: ← Dashboard
A2: # | B2: Machine | C2: Category | D2: Task Description | E2: Priority | F2: Progress | G2: Status | H2: Responsible | I2: Deadline | J2: Remarks
A3: 1 | B3: Accumulator | C3: Electrical | D3: Dry run | E3: High | F3: 0 | G3: Not Started | H3: Arsalan | J3: on machine testing
A4: 2 | B4: Accumulator | C4: Mechanical | D4: chain & bearing greasing | E4: Medium | F4: 0.5 | G4: In Progress | H4: Arsalan
A5: 3 | B5: Auto strapping machine | C5: Mechanical | D5: to place and install at designated location | E5: Medium | F5: 0 | G5: Not Started | H5: Arsalan
A6: 4 | B6: Auto strapping machine | C6: Mechanical | D6: Dry run | E6: Low | F6: 0 | G6: Not Started | H6: Arsalan
A7: 5 | B7: Auto strapping machine | C7: Electrical | D7: wiring and connections to be done | E7: Medium | F7: 0 | G7: Not Started | H7: Arsalan
A8: 6 | B8: Lacquer | C8: Electrical | D8: All heaters — check, fix or replace faulty | E8: High | F8: 1 | G8: Completed | H8: Arsalan | I8: 46157
A9: 7 | B9: Press | C9: Mechanical | D9: Press & Trimming compressor temporary line fixed | E9: High | F9: 1 | G9: Completed | H9: Arsalan | I9: 46158
A10: 8 | B10: Lacquer | C10: Electrical | D10: Blower main motor connection and testing | E10: High | F10: 1 | G10: Completed | H10: Arsalan | I10: 46183
A11: 9 | B11: Lacquer | C11: Mechanical | D11: Spray Guns — cleaned with thinner | E11: High | F11: 1 | G11: Completed | H11: Saqib | I11: 46183
A12: 10 | B12: Lacquer | C12: Mechanical | D12: Spray Mount Drum — scraped & cleaned | E12: High | F12: 1 | G12: Completed | H12: Saqib | I12: 46183
A13: 11 | B13: Lacquer | C13: Mechanical | D13: Mandrel Plate — scraped & cleaned | E13: Medium | F13: 1 | G13: Completed | H13: Saqib | I13: 46183
A14: 12 | B14: Lacquer | C14: Mechanical | D14: Exhaust Sieve — cleaned | E14: Medium | F14: 1 | G14: Completed | H14: Saqib | I14: 46183
A15: 13 | B15: Lacquer | C15: Mechanical | D15: Frame Body — cleaned | E15: Medium | F15: 1 | G15: Completed | H15: Saqib | I15: 46183
A16: 14 | B16: Lacquer | C16: Mechanical | D16: Oven Chain cleaning | E16: Medium | F16: 1 | G16: Completed | H16: Saqib | I16: 46183
A17: 15 | B17: Washing | C17: Mechanical | D17: chain installation | E17: High | F17: 1 | G17: Completed | H17: Arsalan | I17: 46184
A18: 16 | B18: Compressor | C18: Electrical | D18: Compressor dryer and auto drain electrical connection | E18: High | F18: 1 | G18: Completed | H18: Arsalan
A19: 17 | B19: Compressor | C19: Mechanical | D19: Compressor piping — dryer and auto drain system | E19: High | F19: 1 | G19: Completed | H19: Arsalan
A20: 18 | B20: Compressor | C20: Mechanical | D20: main pipe to be elevated downward for smooth drainage | E20: Medium | F20: 0 | G20: Not Started | H20: Arsalan
A21: 19 | B21: Compressor | C21: Mechanical | D21: individual section pipes/ branches to be supported/fixed/welded | E21: Medium | F21: 0 | G21: Not Started | H21: Arsalan
A22: 20 | B22: Compressor | C22: Electrical | D22: dryer wiring and connection to be done. | E22: High | F22: 1 | G22: Completed | H22: Arsalan
A23: 21 | B23: decoration Oven | C23: Electrical | D23: Heaters to be checked and replaced if required | E23: High | F23: 0 | G23: Not Started | H23: Arsalan | J23: sample needed for ordering
A24: 22 | B24: decoration Oven | C24: Electrical | D24: Blower motor connection and testing | E24: High | F24: 1 | G24: Completed | H24: Arsalan
A25: 23 | B25: decoration Oven | C25: Electrical | D25: temperature gauges to be checked & installed | E25: High | F25: 0 | G25: Not Started | H25: Arsalan
A26: 24 | B26: decoration Oven | C26: General | D26: Oven Dry run | E26: High | F26: 0 | G26: Not Started | H26: Arsalan | J26: Cleaning in progress & Heater testing in progress
A27: 25 | B27: decoration Oven | C27: Mechanical | D27: Motors alignment w.r.t marking | E27: High | F27: 1 | G27: Completed | H27: Arsalan | J27: Khalid Shb observations
A28: 26 | B28: FG Conveyor | C28: Mechanical | D28: Realignment of conveyor to be done as per Lindsay recommendation | E28: Medium | F28: 0 | G28: Not Started | H28: Arsalan
A29: 27 | B29: FG Conveyor | C29: Electrical | D29: connection/wiring to be done | E29: Medium | F29: 0 | G29: Not Started | H29: Arsalan
A30: 28 | B30: General | C30: General | D30: Machine Operating Manuals | E30: Medium | F30: 0.1 | G30: In Progress | H30: Saqib
A31: 29 | B31: General | C31: General | D31: Overall machine paint | E31: Medium | F31: 0 | G31: Not Started | H31: Saqib
A32: 30 | B32: General | C32: Mechanical | D32: Modify exhaust duct pipes — prevent rainwater entry bends installation | E32: Medium | F32: 1 | G32: Completed | H32: Saqib
A33: 31 | B33: General | C33: Mechanical | D33: Test each machine individually without load | E33: Medium | F33: 0.5 | G33: In Progress | H33: Arsalan
A34: 32 | B34: General | C34: General | D34: Ensure proper cleaning of entire machine | E34: Medium | F34: 0.4 | G34: In Progress | H34: Saqib
A35: 33 | B35: General | C35: Mechanical | D35: Scoop required for slug handling | E35: Medium | F35: 0 | G35: In Progress | H35: Saqib
A36: 34 | B36: General | C36: Mechanical | D36: Baling machine procurement | E36: Medium | F36: 0 | G36: Pending Procurement | H36: Saqib
A37: 35 | B37: General | C37: Mechanical | D37: scrap collector container to be made/procured for trimming | E37: Medium | F37: 0 | G37: Not Started | H37: Saqib
A38: 36 | B38: General | C38: Electrical | D38: White LED lighting for printing and oven area | E38: Medium | F38: 0 | G38: Not Started | H38: Saqib
A39: 37 | B39: General | C39: General | D39: Make stands for all spare rolls | E39: Medium | F39: 0 | G39: Not Started | H39: Saqib
... A44: 42 | B44: General | C44: General | D44: Boxes / Bins for cans packing (Alpha Container) | E44: Medium | F44: 0 | G44: Not Started | H44: Saqib
...

Sheet HOW TO UPDATE
B1: HOW TO UPDATE — QUICK GUIDE
B2: COLUMN / STEP | C2: INSTRUCTION
B3: COLUMN | C3: WHAT TO DO | F3: Arsalan
B4: Machine | C4: Click the cell — a dropdown appears. Pick the machine name. | F4: Saqib
B5: Category | C5: Pick Electrical or Mechanical from the dropdown.
B6: Task Description | C6: Type the task clearly and briefly.
B7: Priority | C7: High = urgent / blocking. Medium = important. Low = when possible.
B8: Progress | C8: Type a number: 0 = not started, 50 = halfway done, 100 = complete.
B9: Status | C9: Pick from dropdown: Not Started / In Progress / Completed / Blocked / Pending Procurement.
B10: Remarks | C10: Short notes — vendor, reason for delay, Khalid sb instruction, etc.
B11: Updated | C11: Type today's date when you update any row.
B12: Add a new task | C12: Scroll to the bottom. Type in the next empty row. All dropdowns work there too.
B13: Filter by machine | C13: Click the filter arrow (▼) on the Machine column. Tick only the machine you want.
B14: Hide completed | C14: Click the filter arrow on Status. Untick Completed. Click OK.
B15: Dashboard links | C15: On the Dashboard, click any machine name (underlined blue) to jump straight to it.
B16: Back to Dashboard | C16: In the Tracker, click '← Dashboard' in the top-right corner of the sheet.
